Workbook
Name UPDATE: 'Data Sheet'!$E$1

Sheet Cover
B2: Financial Statement Analysis & Valuation (FSAV)
B3: Term Project
B6: Hindustan Unilever Limited
B7: Fast Moving Consumer Goods | NSE: HINDUNILVR | BSE: 500696
B9: Project Details
B10: Submitted by | C10: Group 8
B11: Submitted to | C11: Dr. Kunal Saigal and Dr. Kriti Sharma
B12: Programme and Section | C12: PGDM - Sec A
B13: Date of submission | C13: 46249
B14: Period of analysis | C14: FY2017 to FY2026 (ten financial years)
B15: Projection period | C15: FY2027E to FY2031E (five years), with a terminal value thereafter
B16: Reporting currency and units | C16: Indian Rupees in crore, unless stated otherwise
B17: Sources of data | C17: Audited annual reports of Hindustan Unilever Ltd., Screener.in and NSE market data
B19: Contents
B20: Worksheet | C20: Purpose
B21: Assumptions Summary | C21: Consolidated list of every assumption used across the project, with its basis
B22: Profit & Loss | C22: Reported statement of profit and loss, FY2017 to FY2026
B23: Balance Sheet | C23: Reported balance sheet, FY2017 to FY2026
B24: Cash Flow | C24: Reported cash flow statement, FY2017 to FY2026
B25: Quarters | C25: Quarterly results used to assess recent operating momentum
B26: Data Sheet | C26: Underlying data extract on which the analysis worksheets are built
B27: Cash Flow Data | C27: Supporting workings for the cash flow analysis
B28: Common Size Statement | C28: Vertical analysis of the profit and loss account and balance sheet
B29: Comparative Statement | C29: Horizontal (year on year) analysis of the financial statements
B30: Ratio analysis | C30: Liquidity, profitability, efficiency, solvency and market ratios
B31: Altman Z Score | C31: Assessment of financial distress and bankruptcy risk
... B38: Customization | C38: Settings used by the source data template

Sheet Dashboard
A1: Hindustan Unilever Ltd. — Financial Dashboard
A2: Key Metrics & Trend Analysis | FY2017–FY2026 | Rs. crore unless stated otherwise
A4: KEY METRICS — FY2026
B5: REVENUE (RS. CR) | F5: NET PROFIT (RS. CR) | J5: NET PROFIT MARGIN | N5: RETURN ON EQUITY
B6: ='Profit & Loss'!K4 -> 64468 | F6: ='Profit & Loss'!K12 -> 15040 | J6: ='Ratio analysis'!L10 -> 0.23329404 | N6: ='Ratio analysis'!L12 -> 0.30649779
B8: EPS (RS.) | F8: P/E RATIO (X) | J8: CURRENT RATIO (X) | N8: DEBT-EQUITY (X)
B9: ='Profit & Loss'!K13 -> 64.010895 | F9: ='Ratio analysis'!L28 -> 32.107034 | J9: ='Ratio analysis'!L4 -> 0.57826632 | N9: ='Ratio analysis'!L22 -> 0.060239859
A11: CHARTS
A98: CHART SOURCE DATA — feeds the charts above, do not delete
A100: Year | B100: Revenue (Rs. cr) | C100: Net Profit (Rs. cr)
A101: {=INDEX('Ratio analysis'!$C$2:$L$2,ROW()-100)} -> FY17 | B101: {=INDEX('Profit & Loss'!$B$4:$K$4,ROW()-100)} -> 33162 | C101: {=INDEX('Profit & Loss'!$B$12:$K$12,ROW()-100)} -> 4476
A102: {=INDEX('Ratio analysis'!$C$2:$L$2,ROW()-100)} -> FY18 | B102: {=INDEX('Profit & Loss'!$B$4:$K$4,ROW()-100)} -> 35545 | C102: {=INDEX('Profit & Loss'!$B$12:$K$12,ROW()-100)} -> 5214
A103: {=INDEX('Ratio analysis'!$C$2:$L$2,ROW()-100)} -> FY19 | B103: {=INDEX('Profit & Loss'!$B$4:$K$4,ROW()-100)} -> 39310 | C103: {=INDEX('Profit & Loss'!$B$12:$K$12,ROW()-100)} -> 6054
A104: {=INDEX('Ratio analysis'!$C$2:$L$2,ROW()-100)} -> FY20 | B104: {=INDEX('Profit & Loss'!$B$4:$K$4,ROW()-100)} -> 39783 | C104: {=INDEX('Profit & Loss'!$B$12:$K$12,ROW()-100)} -> 6748
A105: {=INDEX('Ratio analysis'!$C$2:$L$2,ROW()-100)} -> FY21 | B105: {=INDEX('Profit & Loss'!$B$4:$K$4,ROW()-100)} -> 47028 | C105: {=INDEX('Profit & Loss'!$B$12:$K$12,ROW()-100)} -> 7995
A106: {=INDEX('Ratio analysis'!$C$2:$L$2,ROW()-100)} -> FY22 | B106: {=INDEX('Profit & Loss'!$B$4:$K$4,ROW()-100)} -> 52446 | C106: {=INDEX('Profit & Loss'!$B$12:$K$12,ROW()-100)} -> 8879
A107: {=INDEX('Ratio analysis'!$C$2:$L$2,ROW()-100)} -> FY23 | B107: {=INDEX('Profit & Loss'!$B$4:$K$4,ROW()-100)} -> 60580 | C107: {=INDEX('Profit & Loss'!$B$12:$K$12,ROW()-100)} -> 10120
A108: {=INDEX('Ratio analysis'!$C$2:$L$2,ROW()-100)} -> FY24 | B108: {=INDEX('Profit & Loss'!$B$4:$K$4,ROW()-100)} -> 61896 | C108: {=INDEX('Profit & Loss'!$B$12:$K$12,ROW()-100)} -> 10277
A109: {=INDEX('Ratio analysis'!$C$2:$L$2,ROW()-100)} -> FY25 | B109: {=INDEX('Profit & Loss'!$B$4:$K$4,ROW()-100)} -> 61328 | C109: {=INDEX('Profit & Loss'!$B$12:$K$12,ROW()-100)} -> 10649
A110: {=INDEX('Ratio analysis'!$C$2:$L$2,ROW()-100)} -> FY26 | B110: {=INDEX('Profit & Loss'!$B$4:$K$4,ROW()-100)} -> 64468 | C110: {=INDEX('Profit & Loss'!$B$12:$K$12,ROW()-100)} -> 15040
A112: Year | B112: Operating Profit Margin | C112: Net Profit Margin
A113: {=INDEX('Ratio analysis'!$C$2:$L$2,ROW()-112)} -> FY17 | B113: {=INDEX('Ratio analysis'!$C$9:$L$9,ROW()-112)} -> 0.19606779 | C113: {=INDEX('Ratio analysis'!$C$10:$L$10,ROW()-112)} -> 0.13497377
A114: {=INDEX('Ratio analysis'!$C$2:$L$2,ROW()-112)} -> FY18 | B114: {=INDEX('Ratio analysis'!$C$9:$L$9,ROW()-112)} -> 0.20627374 | C114: {=INDEX('Ratio analysis'!$C$10:$L$10,ROW()-112)} -> 0.1466873
A115: {=INDEX('Ratio analysis'!$C$2:$L$2,ROW()-112)} -> FY19 | B115: {=INDEX('Ratio analysis'!$C$9:$L$9,ROW()-112)} -> 0.21971509 | C115: {=INDEX('Ratio analysis'!$C$10:$L$10,ROW()-112)} -> 0.15400661
A116: {=INDEX('Ratio analysis'!$C$2:$L$2,ROW()-112)} -> FY20 | B116: {=INDEX('Ratio analysis'!$C$9:$L$9,ROW()-112)} -> 0.23334087 | C116: {=INDEX('Ratio analysis'!$C$10:$L$10,ROW()-112)} -> 0.16962019
A117: {=INDEX('Ratio analysis'!$C$2:$L$2,ROW()-112)} -> FY21 | B117: {=INDEX('Ratio analysis'!$C$9:$L$9,ROW()-112)} -> 0.22799183 | C117: {=INDEX('Ratio analysis'!$C$10:$L$10,ROW()-112)} -> 0.1700051
A118: {=INDEX('Ratio analysis'!$C$2:$L$2,ROW()-112)} -> FY22 | B118: {=INDEX('Ratio analysis'!$C$9:$L$9,ROW()-112)} -> 0.22852076 | C118: {=INDEX('Ratio analysis'!$C$10:$L$10,ROW()-112)} -> 0.16929794
A119: {=INDEX('Ratio analysis'!$C$2:$L$2,ROW()-112)} -> FY23 | B119: {=INDEX('Ratio analysis'!$C$9:$L$9,ROW()-112)} -> 0.22215253 | C119: {=INDEX('Ratio analysis'!$C$10:$L$10,ROW()-112)} -> 0.16705183
A120: {=INDEX('Ratio analysis'!$C$2:$L$2,ROW()-112)} -> FY24 | B120: {=INDEX('Ratio analysis'!$C$9:$L$9,ROW()-112)} -> 0.23038645 | C120: {=INDEX('Ratio analysis'!$C$10:$L$10,ROW()-112)} -> 0.16603658
A121: {=INDEX('Ratio analysis'!$C$2:$L$2,ROW()-112)} -> FY25 | B121: {=INDEX('Ratio analysis'!$C$9:$L$9,ROW()-112)} -> 0.24132533 | C121: {=INDEX('Ratio analysis'!$C$10:$L$10,ROW()-112)} -> 0.1736401
A122: {=INDEX('Ratio analysis'!$C$2:$L$2,ROW()-112)} -> FY26 | B122: {=INDEX('Ratio analysis'!$C$9:$L$9,ROW()-112)} -> 0.28896507 | C122: {=INDEX('Ratio analysis'!$C$10:$L$10,ROW()-112)} -> 0.23329404
A124: Year | B124: ROA | C124: ROE | D124: ROCE
A125: {=INDEX('Ratio analysis'!$C$2:$L$2,ROW()-124)} -> FY17 | B125: {=INDEX('Ratio analysis'!$C$11:$L$11,ROW()-124)} -> 0.28498663 | C125: {=INDEX('Ratio analysis'!$C$12:$L$12,ROW()-124)} -> 0.66370107 | D125: {=INDEX('Ratio analysis'!$C$13:$L$13,ROW()-124)} -> 0.96411625
A126: {=INDEX('Ratio analysis'!$C$2:$L$2,ROW()-124)} -> FY18 | B126: {=INDEX('Ratio analysis'!$C$11:$L$11,ROW()-124)} -> 0.310653 | C126: {=INDEX('Ratio analysis'!$C$12:$L$12,ROW()-124)} -> 0.74352941 | D126: {=INDEX('Ratio analysis'!$C$13:$L$13,ROW()-124)} -> 1.0455615
A127: {=INDEX('Ratio analysis'!$C$2:$L$2,ROW()-124)} -> FY19 | B127: {=INDEX('Ratio analysis'!$C$11:$L$11,ROW()-124)} -> 0.33180784 | C127: {=INDEX('Ratio analysis'!$C$12:$L$12,ROW()-124)} -> 0.79931344 | D127: {=INDEX('Ratio analysis'!$C$13:$L$13,ROW()-124)} -> 1.1403486
A128: {=INDEX('Ratio analysis'!$C$2:$L$2,ROW()-124)} -> FY20 | B128: {=INDEX('Ratio analysis'!$C$11:$L$11,ROW()-124)} -> 0.34799649 | C128: {=INDEX('Ratio analysis'!$C$12:$L$12,ROW()-124)} -> 0.83846918 | D128: {=INDEX('Ratio analysis'!$C$13:$L$13,ROW()-124)} -> 1.1534543
A129: {=INDEX('Ratio analysis'!$C$2:$L$2,ROW()-124)} -> FY21 | B129: {=INDEX('Ratio analysis'!$C$11:$L$11,ROW()-124)} -> 0.17987918 | C129: {=INDEX('Ratio analysis'!$C$12:$L$12,ROW()-124)} -> 0.28603116 | D129: {=INDEX('Ratio analysis'!$C$13:$L$13,ROW()-124)} -> 0.38359301
A130: {=INDEX('Ratio analysis'!$C$2:$L$2,ROW()-124)} -> FY22 | B130: {=INDEX('Ratio analysis'!$C$11:$L$11,ROW()-124)} -> 0.1275297 | C130: {=INDEX('Ratio analysis'!$C$12:$L$12,ROW()-124)} -> 0.18357368 | D130: {=INDEX('Ratio analysis'!$C$13:$L$13,ROW()-124)} -> 0.24779036
A131: {=INDEX('Ratio analysis'!$C$2:$L$2,ROW()-124)} -> FY23 | B131: {=INDEX('Ratio analysis'!$C$11:$L$11,ROW()-124)} -> 0.14096376 | C131: {=INDEX('Ratio analysis'!$C$12:$L$12,ROW()-124)} -> 0.20369345 | D131: {=INDEX('Ratio analysis'!$C$13:$L$13,ROW()-124)} -> 0.27088009
A132: {=INDEX('Ratio analysis'!$C$2:$L$2,ROW()-124)} -> FY24 | B132: {=INDEX('Ratio analysis'!$C$11:$L$11,ROW()-124)} -> 0.13561089 | C132: {=INDEX('Ratio analysis'!$C$12:$L$12,ROW()-124)} -> 0.20245858 | D132: {=INDEX('Ratio analysis'!$C$13:$L$13,ROW()-124)} -> 0.28092433
...

Sheet Key Findings
B2: Key Findings
B3: All figures in this worksheet are linked to the analysis worksheets. Amounts are in Rs. crore unless stated otherwise.
B5: 1. Operating Performance and Profitability
B6: Parameter | C6: FY2025 | D6: FY2026 | E6: Observation
B7: Net sales (Rs. crore) | C7: ='Beneish M-Score'!K5 -> 61328 | D7: ='Beneish M-Score'!L5 -> 64468 | E7: ="Revenue grew by "&TEXT(D7/C7-1,"0.0%")&" in FY2026 after a flat FY2025, indicating a recovery in volume led growth." -> Revenue grew by 5.1% in FY2026 after a flat FY2025, indicating a recovery in volume led growth.
B8: Net profit (Rs. crore) | C8: ='Beneish M-Score'!K16 -> 10649 | D8: ='Beneish M-Score'!L16 -> 15040 | E8: The sharp rise in FY2026 is largely attributable to a one-off divestment gain and a correspondingly low effective tax rate, and is therefore not representative of the underlying business.
B9: Operating profit margin | C9: ='Ratio analysis'!K9 -> 0.24132533 | D9: ='Ratio analysis'!L9 -> 0.28896507 | E9: Margins have improved steadily from 19.6 per cent in FY2017, reflecting premiumisation, cost savings and favourable input prices.
B10: Net profit margin | C10: ='Ratio analysis'!K10 -> 0.1736401 | D10: ='Ratio analysis'!L10 -> 0.23329404 | E10: The reported margin for FY2026 is inflated by the one-off gain; the underlying margin is closer to 17 to 18 per cent.
B11: Return on equity | C11: ='Ratio analysis'!K12 -> 0.21166766 | D11: ='Ratio analysis'!L12 -> 0.30649779 | E11: Return on equity fell sharply after FY2020 because the merger with GSK Consumer Healthcare added a large goodwill and equity base; it has since been rebuilt from 18.4 per cent in FY2022.
B12: Return on capital employed | C12: ='Ratio analysis'!K13 -> 0.29417611 | D12: ='Ratio analysis'!L13 -> 0.37963746 | E12: Returns remain well above the cost of capital of about 9.9 per cent, confirming that the company continues to create economic value.
B14: 2. Liquidity, Efficiency and Solvency
B15: Parameter | C15: FY2025 | D15: FY2026 | E15: Observation
B16: Current ratio | C16: ='Ratio analysis'!K4 -> 0.71873807 | D16: ='Ratio analysis'!L4 -> 0.57826632 | E16: The current ratio is below one and has declined further. This is characteristic of an FMCG business that operates on negative working capital by drawing extended credit from suppliers while selling largely on cash terms.
B17: Quick ratio | C17: ='Ratio analysis'!K5 -> 0.56550862 | D17: ='Ratio analysis'!L5 -> 0.41604282 | E17: Low in absolute terms, but not a concern given the strong and predictable operating cash flows and the negligible level of debt.
B18: Inventory turnover (times) | C18: ='Ratio analysis'!K16 -> 7.3052033 | D18: ='Ratio analysis'!L16 -> 7.2396784 | E18: Stable at about seven times over the entire period, indicating consistent inventory management.
B19: Debtors turnover (times) | C19: ='Ratio analysis'!K17 -> 17.995305 | D19: ='Ratio analysis'!L17 -> 17.912754 | E19: Debtors turnover has fallen from about 30 times in FY2017 to 18 times, showing that receivables are being collected more slowly. This is the clearest area of deterioration in working capital management.
B20: Debt to equity ratio | C20: ='Ratio analysis'!K22 -> 0.065513814 | D20: ='Ratio analysis'!L22 -> 0.060239859 | E20: The company is virtually debt free, which leaves substantial headroom to raise funds should an acquisition opportunity arise.
B21: Interest coverage (times) | C21: ='Ratio analysis'!K23 -> 38.845144 | D21: ='Ratio analysis'!L23 -> 45.436585 | E21: Interest cover of more than forty times means that solvency risk is negligible.
B22: Dividend payout ratio | C22: ='Ratio analysis'!K29 -> 1.1695934 | D22: ='Ratio analysis'!L29 -> 0.640625 | E22: The company has consistently distributed the greater part of its earnings, which is consistent with a mature business that has limited reinvestment requirements.
B24: 3. Earnings Quality and Financial Distress
B25: Test | C25: Result | E25: Interpretation
B26: Beneish M-Score, FY2026 | C26: ='Beneish M-Score'!K32 -> -2.3354644 | E26: ="The score is below the threshold of -1.78, which places the company in the low risk category. There is no statistical indication of earnings manipulation in FY2026." -> The score is below the threshold of -1.78, which places the company in the low risk category. There is no statistical indication of earnings manipulation in FY2026.
B27: Beneish M-Score, FY2021 | C27: ='Beneish M-Score'!F32 -> -1.2381429 | E27: FY2021 is the only year flagged as high risk. This is explained by the merger with GSK Consumer Healthcare, which distorted the sales growth, depreciation and leverage indices, rather than by any evidence of manipulation.
B28: Altman Z-Score, FY2026 | C28: ='Altman Z Score'!I35 -> 6.0734393 | E28: The score is above the safe zone threshold of 3.00 in every year examined — comfortably so from FY2022 to FY2026, and only marginally in FY2020 and FY2021 — so the risk of financial distress is negligible throughout. The absolute value in the later years is inflated because the market capitalisation to long term liabilities component becomes very large when borrowings are near zero; the conclusion, however, is unaffected.
B30: 4. Valuation
B31: Method | C31: Implied value (Rs.) | E31: Comment
B32: Discounted cash flow (base case) | C32: ='DCF Valuation'!C74 -> 1384.4125 | E32: Based on a WACC of 9.9 per cent and a terminal growth rate of 6.0 per cent. The value is highly sensitive to both inputs, as shown in the sensitivity table on the DCF worksheet.
B33: Relative valuation, median EV/EBITDA | C33: ='Relative Valuation'!U26 -> 2639.8646 | E33: Applying the median peer multiple indicates a material undervaluation against the market price.
B34: Relative valuation, median P/E | C34: ='Relative Valuation'!Y26 -> 2810.773 | E34: The peer set trades at a median price to earnings multiple higher than that of the company, which indicates undervaluation on this measure.
B35: Current market price | C35: ='DCF Valuation'!C75 -> 2108 | E35: Closing price on 30 July 2026.
B36: Deviation of the DCF value from the market price | C36: ='DCF Valuation'!C76 -> -0.34325782 | E36: The discounted cash flow model and the market price differ materially. The difference narrows substantially at a lower beta and a higher terminal growth rate, and the balance reflects the premium the market assigns to the brand portfolio and distribution network of the company.
B38: 5. Overall Assessment
B39: Hindustan Unilever remains a financially sound business. Profitability and returns on capital employed are comfortably above the cost of capital, the balance sheet carries almost no debt, and both the Altman Z-Score and the Beneish M-Score indicate that the risk of financial distress and of earnings manipulation is low. The principal areas of weakness are the slower collection of receivables, the persistently negative working capital position and the moderation in revenue growth compared with the earlier part of the period under review. On valuation, the comparable company analysis indicates the share is undervalued against its peers on both an EV/EBITDA and a price-to-earnings basis, while the discounted cash flow model indicates a value materially below the prevailing market price; the blended average across all three methods nevertheless sits close to the current market price. The difference across methods is driven mainly by the beta and terminal growth assumptions used in the DCF and by the premium that the market assigns to the brand portfolio and distribution reach of the company.

Sheet Recommendations
B2: Recommendations
B3: Based on the analysis carried out in the preceding worksheets. Figures are linked to their source worksheets.
B5: 1. Valuation Summary and Investment View
B6: Method | C6: Implied value per share (Rs.) | D6: Premium / (discount) to market price | E6: Signal
B7: Discounted cash flow, base case | C7: ='Key Findings'!C32 -> 1384.4125 | D7: =C7/$C$11-1 -> -0.34325782 | E7: =IF(D7>0.1,"Undervalued",IF(D7<-0.1,"Overvalued","Fairly valued")) -> Overvalued
B8: Relative valuation, median EV/EBITDA | C8: ='Key Findings'!C33 -> 2639.8646 | D8: =C8/$C$11-1 -> 0.25230767 | E8: =IF(D8>0.1,"Undervalued",IF(D8<-0.1,"Overvalued","Fairly valued")) -> Undervalued
B9: Relative valuation, median P/E | C9: ='Key Findings'!C34 -> 2810.773 | D9: =C9/$C$11-1 -> 0.33338378 | E9: =IF(D9>0.1,"Undervalued",IF(D9<-0.1,"Overvalued","Fairly valued")) -> Undervalued
B10: Average of the three methods | C10: =AVERAGE(C7:C9) -> 2278.35 | D10: =C10/$C$11-1 -> 0.080811207 | E10: =IF(D10>0.1,"Undervalued",IF(D10<-0.1,"Overvalued","Fairly valued")) -> Fairly valued
B11: Current market price | C11: ='DCF Valuation'!C75 -> 2108
B13: Recommendation | C13: HOLD
B14: Rationale | C14: The three valuation methods bracket the market price rather than pointing consistently in one direction, and their average is close to the price at which the share currently trades. The business is of high quality, generates returns well above its cost of capital and carries almost no debt, but the price already reflects much of that quality. Existing investors are therefore advised to hold, while fresh purchases are better made on a decline towards the discounted cash flow range, or once volume growth reaccelerates.
B16: 2. Recommendations to Management
B17: Area | C17: Recommendation
B18: Receivables management | C18: Debtors turnover has fallen from about thirty times in FY2017 to eighteen times in FY2026. Tighter credit terms for distributors and closer monitoring of overdue balances would release working capital and improve the cash conversion cycle.
B19: Revenue growth | C19: Growth of about five per cent is close to inflation and implies limited volume expansion. Continued investment in premium and health oriented categories, in rural distribution and in digital channels is necessary to restore mid to high single digit volume growth.
B20: Margin management | C20: Operating margins are at the upper end of their historical range. Further gains should be sought through mix improvement and cost efficiency rather than through price increases, which could weaken volumes in a competitive market.
B21: Capital allocation | C21: With negligible debt and a payout ratio of about sixty four per cent, the company has ample headroom to fund acquisitions in premium and wellness categories, which would support growth beyond the rate assumed in the terminal value.
B22: Disclosure | C22: The one-off divestment gain in FY2026 materially distorts the reported profit and the effective tax rate. Presenting a clear reconciliation of underlying and reported earnings would improve comparability for users of the financial statements.
B24: 3. Key Risks to the Recommendation
B25: Risk | C25: Description
B26: Input cost inflation | C26: A rise in palm oil, crude derivative or tea prices would compress the operating margin of 23.5 per cent assumed throughout the projection period.
B27: Competitive intensity | C27: Regional and direct to consumer brands continue to gain share in several categories, which may limit both volume growth and pricing power.
B28: Rural demand | C28: A weak monsoon or slower rural income growth would directly affect volumes, as rural markets contribute a substantial share of revenue.
B29: Valuation risk | C29: The share trades at a price to earnings multiple well above the peer median. Any disappointment in earnings could lead to a de-rating of the multiple in addition to a fall in earnings.
B30: Assumption risk | C30: The discounted cash flow value moves from roughly Rs. 950 to Rs. 2,740 per share across the range of WACC and terminal growth rates tested, so the conclusion drawn from that model is sensitive to the inputs selected.
B32: 4. Limitations of the Analysis
B33: The analysis is based entirely on published financial statements and market data, and no management guidance or segment level internal data has been used.
B34: Figures from FY2021 onward include the effect of the merger with GSK Consumer Healthcare, which limits comparability with earlier years.
B35: The Asset Quality Index within the Beneish model is held at the neutral value of 1.00 owing to the absence of a separate other non-current asset disclosure.
B36: The Altman Z-Score is inflated by the market capitalisation to long term liabilities component because borrowings are negligible; the classification is nevertheless unaffected.
B37: The comparable company analysis uses four peers only, and no adjustment has been made for differences in size, growth or category mix.

Sheet Assumptions Summary
B2: Summary of Assumptions
B3: This worksheet consolidates every assumption used in the project. Values shown in this sheet are linked to the worksheets in which they are applied, so that any change made there is reflected here.
B5: 1. Projection Assumptions (Discounted Cash Flow Model)
B6: Assumption | C6: Value | D6: Basis
B7: Explicit forecast period | C7: Five years | D7: FY2027E to FY2031E, followed by a terminal value
B8: Revenue growth rate | C8: =TEXT('DCF Valuation'!C7,"0.0%")&" tapering to "&TEXT('DCF Valuation'!G7,"0.0%") -> 8.0% tapering to 6.0% | D8: Tapering from recent momentum of 8 to 10 per cent towards long run FMCG industry growth
B9: Operating profit margin (EBIT) | C9: ='DCF Valuation'!C8 -> 0.235 | D9: Five year historical average operating margin of 23.3 to 24.5 per cent, held constant
B10: Effective tax rate | C10: ='DCF Valuation'!C9 -> 0.26 | D10: Normalised rate; excludes the one-off rate of 17 per cent in FY2026 arising from the divestment
B11: Depreciation and amortisation, as a percentage of revenue | C11: ='DCF Valuation'!C10 -> 0.021 | D11: FY2026 actual: 1,333 / 64,468 = 2.07 per cent
B12: Capital expenditure, as a percentage of revenue | C12: ='DCF Valuation'!C11 -> 0.023 | D12: Marginally above depreciation, to reflect premiumisation led capacity addition
B13: Net working capital, as a percentage of revenue | C13: ='DCF Valuation'!C12 -> 0.054 | D13: FY2026 actual: 3,472 / 64,468 = 5.4 per cent
B14: Terminal growth rate (g) | C14: ='DCF Valuation'!C13 -> 0.06 | D14: Long run growth assumption linked to nominal GDP growth in India
B16: 2. Cost of Capital Assumptions
B17: Assumption | C17: Value | D17: Basis
B18: Risk free rate | C18: ='DCF Valuation'!C20 -> 0.05 | D18: Yield on the 10 year Government of India security, July 2026
B19: Equity beta | C19: ='DCF Valuation'!C22 -> 0.66045291 | D19: Blended estimate; reported betas range from 0.3 to 0.9 depending on source and period
B20: Equity risk premium | C20: ='DCF Valuation'!C21 -> 0.0731 | D20: Equity risk premium for India, commonly taken at 6 to 7 per cent
B21: Cost of equity (Ke) | C21: ='DCF Valuation'!C23 -> 0.098279108 | D21: Capital asset pricing model: Ke = Rf + Beta * ERP
B22: Pre-tax cost of debt | C22: ='DCF Valuation'!C27 -> 0.27740189 | D22: Approximate yield on AAA rated corporate bonds; HUL is rated CRISIL AAA
B23: Post-tax cost of debt | C23: ='DCF Valuation'!C29 -> 0.19418133 | D23: Pre-tax cost of debt adjusted for the effective tax rate
B24: Weight of equity | C24: ='DCF Valuation'!C32 -> 0.995 | D24: Based on market capitalisation as at 30 July 2026 and book value of debt
B25: Weight of debt | C25: ='DCF Valuation'!C31 -> 0.005 | D25: Borrowings are negligible, hence the capital structure is almost entirely equity funded
B26: Weighted average cost of capital (WACC) | C26: ='DCF Valuation'!C35 -> 0.098758619 | D26: WACC = (We * Ke) + (Wd * Kd post-tax); tested from 8.0 to 13.0 per cent in the sensitivity analysis
B28: 3. Assumptions Underlying the Analytical Models
B29: Model | C29: Assumption applied
B30: Altman Z-Score | C30: The original 1968 model for listed manufacturing companies is used, with weights of 1.2, 1.4, 3.3, 0.6 and 1.0. Market value of equity is taken as market capitalisation. Interpretation: above 3.00 is safe, 1.81 to 3.00 is the grey zone and below 1.81 indicates distress.
B31: Beneish M-Score | C31: The eight variable model is used, with a threshold of -1.78. The Asset Quality Index is held at the neutral value of 1.00 because the balance sheet does not disclose a separate other non-current asset line, which makes the standard formula indeterminate. This is a conservative simplification rather than a computed result.
B32: Relative Valuation | C32: The peer set comprises ITC, Nestle India, Godrej Consumer Products and Marico, being listed Indian FMCG companies of comparable business profile. Trailing EV/Revenue, EV/EBITDA, EV/EBIT and P/E multiples are used, and the median peer multiple is applied to the corresponding financial of the company.
B33: Ratio Analysis | C33: Ratios are computed on reported year end figures rather than on averages. Figures from FY2021 onward reflect the merger of GSK Consumer Healthcare, so the balance sheet and the ratios derived from it are not strictly comparable with the earlier years.
B34: Common Size and Comparative Statements | C34: Common size figures are expressed as a percentage of net sales for the profit and loss account and of total assets for the balance sheet. Comparative figures are stated as year on year changes in absolute and percentage terms.
B36: 4. General Assumptions
B37: Assumption | C37: Value
B38: Financial year end | C38: 31 March
B39: Base year for the projections | C39: FY2026 (audited)
B40: Shares outstanding | C40: ='DCF Valuation'!C73&" crore shares of face value Re. 1 each" -> 234.96 crore shares of face value Re. 1 each
B41: Market price used | C41: ="Rs. "&TEXT('DCF Valuation'!C75,"#,##0")&" per share, being the closing price on 30 July 2026" -> Rs. 2,108 per share, being the closing price on 30 July 2026
B42: Units of presentation | C42: Rupees in crore, unless stated otherwise
B43: Treatment of one-off items | C43: The gain arising on divestment in FY2026 and the consequent low effective tax rate are treated as non-recurring and are excluded from the projections.

Sheet Data Sheet
A1: COMPANY NAME | B1: HINDUSTAN UNILEVER LTD | E1: =IF(B2<>B3, "A NEW VERSION OF THE WORKSHEET IS AVAILABLE", "")
A2: LATEST VERSION | B2: 2.1 | E2: PLEASE DO NOT MAKE ANY CHANGES TO THIS SHEET
A3: CURRENT VERSION | B3: 2.1
A5: META
A6: Number of shares | B6: =IF(B9>0, B9/B8, 0) -> 234.94241
A7: Face Value | B7: 1
A8: Current Price | B8: 2100.8
A9: Market Capitalization | B9: 493567.01
A15: PROFIT & LOSS
A16: Report Date | B16: 42825 | C16: 43190 | D16: 43555 | E16: 43921 | F16: 44286 | G16: 44651 | H16: 45016 | I16: 45382 | J16: 45747 | K16: 46112
A17: Sales | B17: 33162 | C17: 35545 | D17: 39310 | E17: 39783 | F17: 47028 | G17: 52446 | H17: 60580 | I17: 61896 | J17: 61328 | K17: 64468
A18: Raw Material Cost | B18: 13606 | C18: 14233 | D18: 15845 | E18: 15697 | F18: 20141 | G18: 22871 | H18: 28427 | I18: 26822 | J18: 26602 | K18: 29158
A19: Change in Inventory | B19: -144 | C19: 72 | D19: -12 | E19: 108 | F19: 405 | G19: 22 | H19: 75 | I19: 11 | J19: 125 | K19: 429
A20: Power and Fuel | B20: 295 | C20: 295 | D20: 308 | E20: 299 | F20: 339 | G20: 318 | H20: 384 | I20: 446 | J20: 403 | K20: 426
A21: Other Mfr. Exp | B21: 2887 | C21: 2998 | D21: 3041 | E21: 2906 | F21: 2868 | G21: 3354 | H21: 3791 | I21: 3385 | J21: 3687 | K21: 3304
A22: Employee Cost | B22: 1743 | C22: 1860 | D22: 1875 | E22: 1820 | F22: 2358 | G22: 2545 | H22: 2854 | I22: 3009 | J22: 2952 | K22: 3175
A23: Selling and admin | B23: 6689 | C23: 7252 | D23: 7796 | E23: 7620 | F23: 7906 | G23: 8164 | H23: 8785 | I23: 10780 | J23: 10145 | K23: 10744
A24: Other Expenses | B24: 1470 | C24: 1480 | D24: 1553 | E24: 1688 | F24: 2195 | G24: 2359 | H24: 2267 | I24: 2806 | J24: 2966 | K24: 3051
A25: Other Income | B25: 606 | C25: 353 | D25: 322 | E25: 424 | F25: 170 | G25: 219 | H25: 448 | I25: 817 | J25: 1355 | K25: 4923
A26: Depreciation | B26: 432 | C26: 520 | D26: 565 | E26: 1002 | F26: 1074 | G26: 1091 | H26: 1137 | I26: 1216 | J26: 1253 | K26: 1333
A27: Interest | B27: 35 | C27: 26 | D27: 33 | E27: 118 | F27: 117 | G27: 106 | H27: 114 | I27: 334 | J27: 381 | K27: 410
... A31: Dividend Amount | B31: 3672 | C31: 4320 | D31: 4752 | E31: 5400 | F31: 9517.5 | G31: 7990 | H31: 9165 | I31: 9870 | J31: 12455 | K31: 9635
A40: Quarters
A41: Report Date | B41: 45382 | C41: 45473 | D41: 45565 | E41: 45657 | F41: 45747 | G41: 45838 | H41: 45930 | I41: 46022 | J41: 46112 | K41: 46203
A42: Sales | B42: 15210 | C42: 15707 | D42: 15926 | E42: 15556 | F42: 15190 | G42: 15757 | H42: 15919 | I42: 16441 | J42: 16351 | K42: 17341
A43: Expenses | B43: 11675 | C43: 11965 | D43: 12139 | E43: 11867 | F43: 11572 | G43: 12118 | H43: 12137 | I43: 12660 | J43: 12514 | K43: 13394
A44: Other Income | B44: 309 | C44: 209 | D44: 203 | E44: 733 | F44: 149 | G44: 103 | H44: 269 | I44: 4048 | J44: 503 | K44: 113
A45: Depreciation | B45: 320 | C45: 329 | D45: 338 | E45: 318 | F45: 318 | G45: 326 | H45: 322 | I45: 337 | J45: 348 | K45: 353
A46: Interest | B46: 105 | C46: 93 | D46: 110 | E46: 109 | F46: 77 | G46: 122 | H46: 124 | I46: 88 | J46: 76 | K46: 75
A47: Profit before tax | B47: 3419 | C47: 3529 | D47: 3542 | E47: 3995 | F47: 3372 | G47: 3294 | H47: 3605 | I47: 7404 | J47: 3916 | K47: 3632
A48: Tax | B48: 858 | C48: 917 | D48: 947 | E48: 1006 | F48: 897 | G48: 526 | H48: 911 | I48: 801 | J48: 922 | K48: 952
A49: Net profit | B49: 2558 | C49: 2610 | D49: 2591 | E49: 2984 | F49: 2464 | G49: 2756 | H49: 2685 | I49: 6607 | J49: 2992 | K49: 2673
A50: Operating Profit | B50: 3535 | C50: 3742 | D50: 3787 | E50: 3689 | F50: 3618 | G50: 3639 | H50: 3782 | I50: 3781 | J50: 3837 | K50: 3947
A55: BALANCE SHEET
A56: Report Date | B56: 42825 | C56: 43190 | D56: 43555 | E56: 43921 | F56: 44286 | G56: 44651 | H56: 45016 | I56: 45382 | J56: 45747 | K56: 46112
A57: Equity Share Capital | B57: 216 | C57: 216 | D57: 216 | E57: 216 | F57: 235 | G57: 235 | H57: 235 | I57: 235 | J57: 235 | K57: 235
A58: Reserves | B58: 6528 | C58: 7065 | D58: 7651 | E58: 8013 | F58: 47439 | G58: 48826 | H58: 50069 | I58: 50983 | J58: 49167 | K58: 48504
A59: Borrowings | B59: 277 | D59: 99 | G59: 1043 | H59: 1219 | I59: 1484 | J59: 1648 | K59: 1478
A60: Other Liabilities | B60: 8685 | C60: 10581 | D60: 10663 | E60: 11924 | F60: 21066 | G60: 20402 | H60: 21554 | I60: 25787 | J60: 28813 | K60: 29521
A61: Total | B61: 15706 | C61: 17862 | D61: 18629 | E61: 20153 | F61: 68740 | G61: 70506 | H61: 73077 | I61: 78489 | J61: 79863 | K61: 79738
...

Sheet Profit & Loss
A1: ='Data Sheet'!B1 -> HINDUSTAN UNILEVER LTD | H1: =UPDATE | M1: SCREENER.IN
A3: Narration | B3: ='Data Sheet'!B16 -> 42825 | C3: ='Data Sheet'!C16 -> 43190 | D3: ='Data Sheet'!D16 -> 43555 | E3: ='Data Sheet'!E16 -> 43921 | F3: ='Data Sheet'!F16 -> 44286 | G3: ='Data Sheet'!G16 -> 44651 | H3: ='Data Sheet'!H16 -> 45016 | I3: ='Data Sheet'!I16 -> 45382 | ... K3: ='Data Sheet'!K16 -> 46112 | L3: Trailing | M3: Best Case | N3: Worst Case
A4: Sales | B4: ='Data Sheet'!B17 -> 33162 | C4: ='Data Sheet'!C17 -> 35545 | D4: ='Data Sheet'!D17 -> 39310 | E4: ='Data Sheet'!E17 -> 39783 | F4: ='Data Sheet'!F17 -> 47028 | G4: ='Data Sheet'!G17 -> 52446 | H4: ='Data Sheet'!H17 -> 60580 | I4: ='Data Sheet'!I17 -> 61896 | ... K4: ='Data Sheet'!K17 -> 64468 | L4: =SUM(Quarters!H4:K4) -> 66052 | M4: =$K4+M23*K4 -> 67768.768 | N4: =$K4+N23*L4 -> 65851.867
A5: Expenses | B5: =SUM('Data Sheet'!B18,'Data Sheet'!B20:B24, -1*'Data Sheet'!B19) -> 26834 | C5: =SUM('Data Sheet'!C18,'Data Sheet'!C20:C24, -1*'Data Sheet'!C19) -> 28046 | D5: =SUM('Data Sheet'!D18,'Data Sheet'!D20:D24, -1*'Data Sheet'!D19) -> 30430 | E5: =SUM('Data Sheet'!E18,'Data Sheet'!E20:E24, -1*'Data Sheet'!E19) -> 29922 | F5: =SUM('Data Sheet'!F18,'Data Sheet'!F20:F24, -1*'Data Sheet'!F19) -> 35402 | G5: =SUM('Data Sheet'!G18,'Data Sheet'!G20:G24, -1*'Data Sheet'!G19) -> 39589 | H5: =SUM('Data Sheet'!H18,'Data Sheet'!H20:H24, -1*'Data Sheet'!H19) -> 46433 | I5: =SUM('Data Sheet'!I18,'Data Sheet'!I20:I24, -1*'Data Sheet'!I19) -> 47237 | ... K5: =SUM('Data Sheet'!K18,'Data Sheet'!K20:K24, -1*'Data Sheet'!K19) -> 49429 | L5: =SUM(Quarters!H5:K5) -> 50705 | M5: =M4-M6 -> 51738.984 | N5: =N4-N6 -> 50551.368
A6: Operating Profit | B6: =B4-B5 -> 6328 | C6: =C4-C5 -> 7499 | D6: =D4-D5 -> 8880 | E6: =E4-E5 -> 9861 | F6: =F4-F5 -> 11626 | G6: =G4-G5 -> 12857 | H6: =H4-H5 -> 14147 | I6: =I4-I5 -> 14659 | ... K6: =K4-K5 -> 15039 | L6: =SUM(Quarters!H6:K6) -> 15347 | M6: =M4*M24 -> 16029.784 | N6: =N4*N24 -> 15300.5
A7: Other Income | B7: ='Data Sheet'!B25 -> 606 | C7: ='Data Sheet'!C25 -> 353 | D7: ='Data Sheet'!D25 -> 322 | E7: ='Data Sheet'!E25 -> 424 | F7: ='Data Sheet'!F25 -> 170 | G7: ='Data Sheet'!G25 -> 219 | H7: ='Data Sheet'!H25 -> 448 | I7: ='Data Sheet'!I25 -> 817 | ... K7: ='Data Sheet'!K25 -> 4923 | L7: =SUM(Quarters!H7:K7) -> 4933 | M7: 0 | N7: 0
A8: Depreciation | B8: ='Data Sheet'!B26 -> 432 | C8: ='Data Sheet'!C26 -> 520 | D8: ='Data Sheet'!D26 -> 565 | E8: ='Data Sheet'!E26 -> 1002 | F8: ='Data Sheet'!F26 -> 1074 | G8: ='Data Sheet'!G26 -> 1091 | H8: ='Data Sheet'!H26 -> 1137 | I8: ='Data Sheet'!I26 -> 1216 | ... K8: ='Data Sheet'!K26 -> 1333 | L8: =SUM(Quarters!H8:K8) -> 1360 | M8: =+$L8 -> 1360 | N8: =+$L8 -> 1360
A9: Interest | B9: ='Data Sheet'!B27 -> 35 | C9: ='Data Sheet'!C27 -> 26 | D9: ='Data Sheet'!D27 -> 33 | E9: ='Data Sheet'!E27 -> 118 | F9: ='Data Sheet'!F27 -> 117 | G9: ='Data Sheet'!G27 -> 106 | H9: ='Data Sheet'!H27 -> 114 | I9: ='Data Sheet'!I27 -> 334 | ... K9: ='Data Sheet'!K27 -> 410 | L9: =SUM(Quarters!H9:K9) -> 363 | M9: =+$L9 -> 363 | N9: =+$L9 -> 363
A10: Profit before tax | B10: ='Data Sheet'!B28 -> 6467 | C10: ='Data Sheet'!C28 -> 7306 | D10: ='Data Sheet'!D28 -> 8604 | E10: ='Data Sheet'!E28 -> 9165 | F10: ='Data Sheet'!F28 -> 10605 | G10: ='Data Sheet'!G28 -> 11879 | H10: ='Data Sheet'!H28 -> 13344 | I10: ='Data Sheet'!I28 -> 13926 | ... K10: ='Data Sheet'!K28 -> 18219 | L10: =SUM(Quarters!H10:K10) -> 18557 | M10: =M6+M7-SUM(M8:M9) -> 14306.784 | N10: =N6+N7-SUM(N8:N9) -> 13577.5
A11: Tax | B11: ='Data Sheet'!B29 -> 1977 | C11: ='Data Sheet'!C29 -> 2079 | D11: ='Data Sheet'!D29 -> 2544 | E11: ='Data Sheet'!E29 -> 2409 | F11: ='Data Sheet'!F29 -> 2606 | G11: ='Data Sheet'!G29 -> 2987 | H11: ='Data Sheet'!H29 -> 3201 | I11: ='Data Sheet'!I29 -> 3644 | ... K11: ='Data Sheet'!K29 -> 3160 | L11: =SUM(Quarters!H11:K11) -> 3586 | M11: =IF($L10>0,$L11/$L10,0) -> 0.19324244 | N11: =IF($L10>0,$L11/$L10,0) -> 0.19324244
A12: Net profit | B12: ='Data Sheet'!B30 -> 4476 | C12: ='Data Sheet'!C30 -> 5214 | D12: ='Data Sheet'!D30 -> 6054 | E12: ='Data Sheet'!E30 -> 6748 | F12: ='Data Sheet'!F30 -> 7995 | G12: ='Data Sheet'!G30 -> 8879 | H12: ='Data Sheet'!H30 -> 10120 | I12: ='Data Sheet'!I30 -> 10277 | ... K12: ='Data Sheet'!K30 -> 15040 | L12: =SUM(Quarters!H12:K12) -> 14957 | M12: =M10-M11*M10 -> 11542.106 | N12: =N10-N11*N10 -> 10953.751
A13: EPS | B13: =IF('Data Sheet'!B93>0,B12/'Data Sheet'!B93,0) -> 20.681052 | C13: =IF('Data Sheet'!C93>0,C12/'Data Sheet'!C93,0) -> 24.088704 | D13: =IF('Data Sheet'!D93>0,D12/'Data Sheet'!D93,0) -> 27.966924 | E13: =IF('Data Sheet'!E93>0,E12/'Data Sheet'!E93,0) -> 31.171471 | F13: =IF('Data Sheet'!F93>0,F12/'Data Sheet'!F93,0) -> 34.027068 | G13: =IF('Data Sheet'!G93>0,G12/'Data Sheet'!G93,0) -> 37.789411 | H13: =IF('Data Sheet'!H93>0,H12/'Data Sheet'!H93,0) -> 43.071161 | I13: =IF('Data Sheet'!I93>0,I12/'Data Sheet'!I93,0) -> 43.73936 | ... K13: =IF('Data Sheet'!K93>0,K12/'Data Sheet'!K93,0) -> 64.010895 | L13: =IF('Data Sheet'!$B6>0,'Profit & Loss'!L12/'Data Sheet'!$B6,0) -> 63.662411 | M13: =IF('Data Sheet'!$B6>0,'Profit & Loss'!M12/'Data Sheet'!$B6,0) -> 49.127385 | N13: =IF('Data Sheet'!$B6>0,'Profit & Loss'!N12/'Data Sheet'!$B6,0) -> 46.623131
A14: Price to earning | B14: =IF(B15>0,B15/B13,"") -> 42.193696 | C14: =IF(C15>0,C15/C13,"") -> 52.975453 | D14: =IF(D15>0,D15/D13,"") -> 58.409356 | E14: =IF(E15>0,E15/E13,"") -> 70.571903 | F14: =IF(F15>0,F15/F13,"") -> 68.390258 | G14: =IF(G15>0,G15/G13,"") -> 51.884905 | H14: =IF(H15>0,H15/H13,"") -> 56.892824 | I14: =IF(I15>0,I15/I13,"") -> 49.546678 | ... K14: =IF(K15>0,K15/K13,"") -> 32.107034 | L14: =IF(L13>0,L15/L13,0) -> 32.999065 | M14: =M25 -> 40.588148 | N14: =N25 -> 32.999065
A15: Price | B15: ='Data Sheet'!B90 -> 872.61 | C15: ='Data Sheet'!C90 -> 1276.11 | D15: ='Data Sheet'!D90 -> 1633.53 | E15: ='Data Sheet'!E90 -> 2199.83 | F15: ='Data Sheet'!F90 -> 2327.12 | G15: ='Data Sheet'!G90 -> 1960.7 | H15: ='Data Sheet'!H90 -> 2450.44 | I15: ='Data Sheet'!I90 -> 2167.14 | ... K15: ='Data Sheet'!K90 -> 2055.2 | L15: ='Data Sheet'!B8 -> 2100.8 | N15: =N13*N14 -> 1538.5197
A17: RATIOS:
A18: Dividend Payout | B18: =IF('Data Sheet'!B30>0, 'Data Sheet'!B31/'Data Sheet'!B30, 0) -> 0.82037534 | C18: =IF('Data Sheet'!C30>0, 'Data Sheet'!C31/'Data Sheet'!C30, 0) -> 0.82853855 | D18: =IF('Data Sheet'!D30>0, 'Data Sheet'!D31/'Data Sheet'!D30, 0) -> 0.78493558 | E18: =IF('Data Sheet'!E30>0, 'Data Sheet'!E31/'Data Sheet'!E30, 0) -> 0.80023711 | F18: =IF('Data Sheet'!F30>0, 'Data Sheet'!F31/'Data Sheet'!F30, 0) -> 1.1904315 | G18: =IF('Data Sheet'!G30>0, 'Data Sheet'!G31/'Data Sheet'!G30, 0) -> 0.89987611 | H18: =IF('Data Sheet'!H30>0, 'Data Sheet'!H31/'Data Sheet'!H30, 0) -> 0.90563241 | I18: =IF('Data Sheet'!I30>0, 'Data Sheet'!I31/'Data Sheet'!I30, 0) -> 0.960397 | ... K18: =IF('Data Sheet'!K30>0, 'Data Sheet'!K31/'Data Sheet'!K30, 0) -> 0.640625
A19: OPM | B19: =IF(B6>0,B6/B4,0) -> 0.19082082 | C19: =IF(C6>0,C6/C4,0) -> 0.21097201 | D19: =IF(D6>0,D6/D4,0) -> 0.22589672 | E19: =IF(E6>0,E6/E4,0) -> 0.24786969 | F19: =IF(F6>0,F6/F4,0) -> 0.24721443 | G19: =IF(G6>0,G6/G4,0) -> 0.24514739 | H19: =IF(H6>0,H6/H4,0) -> 0.23352592 | I19: =IF(I6>0,I6/I4,0) -> 0.23683275 | ... L19: =IF(L6>0,L6/L4,0) -> 0.23234724
G22: TRENDS: | H22: 10 YEARS | I22: 7 YEARS | J22: 5 YEARS | K22: 3 YEARS | L22: RECENT | M22: BEST | N22: WORST
G23: Sales Growth | H23: =IF(B4=0,"",POWER($K4/B4,1/9)-1) -> 0.076658974 | I23: =IF(D4=0,"",POWER($K4/D4,1/7)-1) -> 0.073227008 | J23: =IF(F4=0,"",POWER($K4/F4,1/5)-1) -> 0.065117542 | K23: =IF(H4=0,"",POWER($K4/H4, 1/3)-1) -> 0.020951182 | L23: =IF(ISERROR(MAX(IF(J4=0,"",(K4-J4)/J4),IF(K4=0,"",(L4-K4)/K4))),"",MAX(IF(J4=0,"",(K4-J4)/J4),IF(K4=0,"",(L4-K4)/K4))) -> 0.051200104 | M23: =MAX(K23:L23) -> 0.051200104 | N23: =MIN(H23:L23) -> 0.020951182
G24: OPM | H24: =IF(SUM(B4:$K$4)=0,"",SUMPRODUCT(B19:$K$19,B4:$K$4)/SUM(B4:$K$4)) -> 0.23326593 | I24: =IF(SUM(E4:$K$4)=0,"",SUMPRODUCT(E19:$K$19,E4:$K$4)/SUM(E4:$K$4)) -> 0.23969045 | J24: =IF(SUM(G4:$K$4)=0,"",SUMPRODUCT(G19:$K$19,G4:$K$4)/SUM(G4:$K$4)) -> 0.23743175 | K24: =IF(SUM(I4:$K$4)=0, "", SUMPRODUCT(I19:$K$19,I4:$K$4)/SUM(I4:$K$4)) -> 0.23653645 | L24: =L19 -> 0.23234724 | M24: =MAX(K24:L24) -> 0.23653645 | N24: =MIN(H24:L24) -> 0.23234724
G25: Price to Earning | H25: =IF(ISERROR(AVERAGEIF(B14:$L14,">0")),"",AVERAGEIF(B14:$L14,">0")) -> 51.242817 | I25: =IF(ISERROR(AVERAGEIF(E14:$L14,">0")),"",AVERAGEIF(E14:$L14,">0")) -> 51.26156 | J25: =IF(ISERROR(AVERAGEIF(G14:$L14,">0")),"",AVERAGEIF(G14:$L14,">0")) -> 45.188387 | K25: =IF(ISERROR(AVERAGEIF(I14:$L14,">0")),"",AVERAGEIF(I14:$L14,">0")) -> 40.588148 | L25: =L14 -> 32.999065 | M25: =MAX(K25:L25) -> 40.588148 | N25: =MIN(H25:L25) -> 32.999065

Sheet Balance Sheet
A1: ='Profit & Loss'!A1 -> HINDUSTAN UNILEVER LTD | E1: =UPDATE | J1: SCREENER.IN
A3: Narration | B3: ='Data Sheet'!B56 -> 42825 | C3: ='Data Sheet'!C56 -> 43190 | D3: ='Data Sheet'!D56 -> 43555 | E3: ='Data Sheet'!E56 -> 43921 | F3: ='Data Sheet'!F56 -> 44286 | G3: ='Data Sheet'!G56 -> 44651 | H3: ='Data Sheet'!H56 -> 45016 | I3: ='Data Sheet'!I56 -> 45382 | ... K3: ='Data Sheet'!K56 -> 46112
A4: Equity Share Capital | B4: ='Data Sheet'!B57 -> 216 | C4: ='Data Sheet'!C57 -> 216 | D4: ='Data Sheet'!D57 -> 216 | E4: ='Data Sheet'!E57 -> 216 | F4: ='Data Sheet'!F57 -> 235 | G4: ='Data Sheet'!G57 -> 235 | H4: ='Data Sheet'!H57 -> 235 | I4: ='Data Sheet'!I57 -> 235 | ... K4: ='Data Sheet'!K57 -> 235
A5: Reserves | B5: ='Data Sheet'!B58 -> 6528 | C5: ='Data Sheet'!C58 -> 7065 | D5: ='Data Sheet'!D58 -> 7651 | E5: ='Data Sheet'!E58 -> 8013 | F5: ='Data Sheet'!F58 -> 47439 | G5: ='Data Sheet'!G58 -> 48826 | H5: ='Data Sheet'!H58 -> 50069 | I5: ='Data Sheet'!I58 -> 50983 | ... K5: ='Data Sheet'!K58 -> 48504
A6: Borrowings | B6: ='Data Sheet'!B59 -> 277 | C6: ='Data Sheet'!C59 -> 0 | D6: ='Data Sheet'!D59 -> 99 | E6: ='Data Sheet'!E59 -> 0 | F6: ='Data Sheet'!F59 -> 0 | G6: ='Data Sheet'!G59 -> 1043 | H6: ='Data Sheet'!H59 -> 1219 | I6: ='Data Sheet'!I59 -> 1484 | ... K6: ='Data Sheet'!K59 -> 1478
A7: Other Liabilities | B7: ='Data Sheet'!B60 -> 8685 | C7: ='Data Sheet'!C60 -> 10581 | D7: ='Data Sheet'!D60 -> 10663 | E7: ='Data Sheet'!E60 -> 11924 | F7: ='Data Sheet'!F60 -> 21066 | G7: ='Data Sheet'!G60 -> 20402 | H7: ='Data Sheet'!H60 -> 21554 | I7: ='Data Sheet'!I60 -> 25787 | ... K7: ='Data Sheet'!K60 -> 29521
A8: Total | B8: ='Data Sheet'!B61 -> 15706 | C8: ='Data Sheet'!C61 -> 17862 | D8: ='Data Sheet'!D61 -> 18629 | E8: ='Data Sheet'!E61 -> 20153 | F8: ='Data Sheet'!F61 -> 68740 | G8: ='Data Sheet'!G61 -> 70506 | H8: ='Data Sheet'!H61 -> 73077 | I8: ='Data Sheet'!I61 -> 78489 | ... K8: ='Data Sheet'!K61 -> 79738
A10: Net Block | B10: ='Data Sheet'!B62 -> 4419 | C10: ='Data Sheet'!C62 -> 4528 | D10: ='Data Sheet'!D62 -> 4715 | E10: ='Data Sheet'!E62 -> 5479 | F10: ='Data Sheet'!F62 -> 51443 | G10: ='Data Sheet'!G62 -> 51473 | H10: ='Data Sheet'!H62 -> 52678 | I10: ='Data Sheet'!I62 -> 53744 | ... K10: ='Data Sheet'!K62 -> 57428
A11: Capital Work in Progress | B11: ='Data Sheet'!B63 -> 229 | C11: ='Data Sheet'!C63 -> 461 | D11: ='Data Sheet'!D63 -> 406 | E11: ='Data Sheet'!E63 -> 597 | F11: ='Data Sheet'!F63 -> 745 | G11: ='Data Sheet'!G63 -> 1313 | H11: ='Data Sheet'!H63 -> 1132 | I11: ='Data Sheet'!I63 -> 1025 | ... K11: ='Data Sheet'!K63 -> 880
A12: Investments | B12: ='Data Sheet'!B64 -> 3794 | C12: ='Data Sheet'!C64 -> 2873 | D12: ='Data Sheet'!D64 -> 2716 | E12: ='Data Sheet'!E64 -> 1255 | F12: ='Data Sheet'!F64 -> 2709 | G12: ='Data Sheet'!G64 -> 3521 | H12: ='Data Sheet'!H64 -> 2882 | I12: ='Data Sheet'!I64 -> 4625 | ... K12: ='Data Sheet'!K64 -> 4359
A13: Other Assets | B13: ='Data Sheet'!B65 -> 7264 | C13: ='Data Sheet'!C65 -> 10000 | D13: ='Data Sheet'!D65 -> 10792 | E13: ='Data Sheet'!E65 -> 12822 | F13: ='Data Sheet'!F65 -> 13843 | G13: ='Data Sheet'!G65 -> 14199 | H13: ='Data Sheet'!H65 -> 16385 | I13: ='Data Sheet'!I65 -> 19095 | ... K13: ='Data Sheet'!K65 -> 17071
A14: Total | B14: ='Data Sheet'!B66 -> 15706 | C14: ='Data Sheet'!C66 -> 17862 | D14: ='Data Sheet'!D66 -> 18629 | E14: ='Data Sheet'!E66 -> 20153 | F14: ='Data Sheet'!F66 -> 68740 | G14: ='Data Sheet'!G66 -> 70506 | H14: ='Data Sheet'!H66 -> 73077 | I14: ='Data Sheet'!I66 -> 78489 | ... K14: ='Data Sheet'!K66 -> 79738
A16: Working Capital | B16: =B13-B7 -> -1421 | C16: =C13-C7 -> -581 | D16: =D13-D7 -> 129 | E16: =E13-E7 -> 898 | F16: =F13-F7 -> -7223 | G16: =G13-G7 -> -6203 | H16: =H13-H7 -> -5169 | I16: =I13-I7 -> -6692 | ... K16: =K13-K7 -> -12450
A17: Debtors | B17: ='Data Sheet'!B67 -> 1085 | C17: ='Data Sheet'!C67 -> 1310 | D17: ='Data Sheet'!D67 -> 1816 | E17: ='Data Sheet'!E67 -> 1149 | F17: ='Data Sheet'!F67 -> 1758 | G17: ='Data Sheet'!G67 -> 2236 | H17: ='Data Sheet'!H67 -> 3079 | I17: ='Data Sheet'!I67 -> 2997 | ... K17: ='Data Sheet'!K67 -> 3379
A18: Inventory | B18: ='Data Sheet'!B68 -> 2541 | C18: ='Data Sheet'!C68 -> 2513 | D18: ='Data Sheet'!D68 -> 2574 | E18: ='Data Sheet'!E68 -> 2767 | F18: ='Data Sheet'!F68 -> 3579 | G18: ='Data Sheet'!G68 -> 4096 | H18: ='Data Sheet'!H68 -> 4251 | I18: ='Data Sheet'!I68 -> 4022 | ... K18: ='Data Sheet'!K68 -> 4789
A20: Debtor Days | B20: =IF('Profit & Loss'!B4>0,'Balance Sheet'!B17/('Profit & Loss'!B4/365),0) -> 11.942133 | C20: =IF('Profit & Loss'!C4>0,'Balance Sheet'!C17/('Profit & Loss'!C4/365),0) -> 13.451962 | D20: =IF('Profit & Loss'!D4>0,'Balance Sheet'!D17/('Profit & Loss'!D4/365),0) -> 16.861867 | E20: =IF('Profit & Loss'!E4>0,'Balance Sheet'!E17/('Profit & Loss'!E4/365),0) -> 10.541814 | F20: =IF('Profit & Loss'!F4>0,'Balance Sheet'!F17/('Profit & Loss'!F4/365),0) -> 13.644425 | G20: =IF('Profit & Loss'!G4>0,'Balance Sheet'!G17/('Profit & Loss'!G4/365),0) -> 15.56153 | H20: =IF('Profit & Loss'!H4>0,'Balance Sheet'!H17/('Profit & Loss'!H4/365),0) -> 18.551255 | I20: =IF('Profit & Loss'!I4>0,'Balance Sheet'!I17/('Profit & Loss'!I4/365),0) -> 17.673275 | ... K20: =IF('Profit & Loss'!K4>0,'Balance Sheet'!K17/('Profit & Loss'!K4/365),0) -> 19.130964
A21: Inventory Turnover | B21: =IF('Balance Sheet'!B18>0,'Profit & Loss'!B4/'Balance Sheet'!B18,0) -> 13.050767 | C21: =IF('Balance Sheet'!C18>0,'Profit & Loss'!C4/'Balance Sheet'!C18,0) -> 14.144449 | D21: =IF('Balance Sheet'!D18>0,'Profit & Loss'!D4/'Balance Sheet'!D18,0) -> 15.27195 | E21: =IF('Balance Sheet'!E18>0,'Profit & Loss'!E4/'Balance Sheet'!E18,0) -> 14.377665 | F21: =IF('Balance Sheet'!F18>0,'Profit & Loss'!F4/'Balance Sheet'!F18,0) -> 13.139983 | G21: =IF('Balance Sheet'!G18>0,'Profit & Loss'!G4/'Balance Sheet'!G18,0) -> 12.804199 | H21: =IF('Balance Sheet'!H18>0,'Profit & Loss'!H4/'Balance Sheet'!H18,0) -> 14.250765 | I21: =IF('Balance Sheet'!I18>0,'Profit & Loss'!I4/'Balance Sheet'!I18,0) -> 15.389359 | ... K21: =IF('Balance Sheet'!K18>0,'Profit & Loss'!K4/'Balance Sheet'!K18,0) -> 13.461683
A23: Return on Equity | B23: =IF(SUM('Balance Sheet'!B4:B5)>0,'Profit & Loss'!B12/SUM('Balance Sheet'!B4:B5),"") -> 0.66370107 | C23: =IF(SUM('Balance Sheet'!C4:C5)>0,'Profit & Loss'!C12/SUM('Balance Sheet'!C4:C5),"") -> 0.71611042 | D23: =IF(SUM('Balance Sheet'!D4:D5)>0,'Profit & Loss'!D12/SUM('Balance Sheet'!D4:D5),"") -> 0.76954366 | E23: =IF(SUM('Balance Sheet'!E4:E5)>0,'Profit & Loss'!E12/SUM('Balance Sheet'!E4:E5),"") -> 0.82002673 | F23: =IF(SUM('Balance Sheet'!F4:F5)>0,'Profit & Loss'!F12/SUM('Balance Sheet'!F4:F5),"") -> 0.16770147 | G23: =IF(SUM('Balance Sheet'!G4:G5)>0,'Profit & Loss'!G12/SUM('Balance Sheet'!G4:G5),"") -> 0.18097878 | H23: =IF(SUM('Balance Sheet'!H4:H5)>0,'Profit & Loss'!H12/SUM('Balance Sheet'!H4:H5),"") -> 0.20117684 | I23: =IF(SUM('Balance Sheet'!I4:I5)>0,'Profit & Loss'!I12/SUM('Balance Sheet'!I4:I5),"") -> 0.20065211 | ... K23: =IF(SUM('Balance Sheet'!K4:K5)>0,'Profit & Loss'!K12/SUM('Balance Sheet'!K4:K5),"") -> 0.30858245
A24: Return on Capital Emp | C24: =IF((B4+B5+B6+C4+C5+C6)>0,('Profit & Loss'!C10+'Profit & Loss'!C9)*2/(B4+B5+B6+C4+C5+C6),"") -> 1.0253111 | D24: =IF((C4+C5+C6+D4+D5+D6)>0,('Profit & Loss'!D10+'Profit & Loss'!D9)*2/(C4+C5+C6+D4+D5+D6),"") -> 1.1329442 | E24: =IF((D4+D5+D6+E4+E5+E6)>0,('Profit & Loss'!E10+'Profit & Loss'!E9)*2/(D4+D5+D6+E4+E5+E6),"") -> 1.1464032 | F24: =IF((E4+E5+E6+F4+F5+F6)>0,('Profit & Loss'!F10+'Profit & Loss'!F9)*2/(E4+E5+E6+F4+F5+F6),"") -> 0.38359301 | G24: =IF((F4+F5+F6+G4+G5+G6)>0,('Profit & Loss'!G10+'Profit & Loss'!G9)*2/(F4+F5+F6+G4+G5+G6),"") -> 0.24514717 | H24: =IF((G4+G5+G6+H4+H5+H6)>0,('Profit & Loss'!H10+'Profit & Loss'!H9)*2/(G4+G5+G6+H4+H5+H6),"") -> 0.26485088 | I24: =IF((H4+H5+H6+I4+I5+I6)>0,('Profit & Loss'!I10+'Profit & Loss'!I9)*2/(H4+H5+H6+I4+I5+I6),"") -> 0.27363876 | J24: =IF((I4+I5+I6+J4+J5+J6)>0,('Profit & Loss'!J10+'Profit & Loss'!J9)*2/(I4+I5+I6+J4+J5+J6),"") -> 0.28529571 | K24: =IF((J4+J5+J6+K4+K5+K6)>0,('Profit & Loss'!K10+'Profit & Loss'!K9)*2/(J4+J5+J6+K4+K5+K6),"") -> 0.36791847

Sheet Cash Flow
A1: ='Balance Sheet'!A1 -> HINDUSTAN UNILEVER LTD | E1: =UPDATE | J1: SCREENER.IN
A3: Narration | B3: ='Data Sheet'!B81 -> 42825 | C3: ='Data Sheet'!C81 -> 43190 | D3: ='Data Sheet'!D81 -> 43555 | E3: ='Data Sheet'!E81 -> 43921 | F3: ='Data Sheet'!F81 -> 44286 | G3: ='Data Sheet'!G81 -> 44651 | H3: ='Data Sheet'!H81 -> 45016 | I3: ='Data Sheet'!I81 -> 45382 | ... K3: ='Data Sheet'!K81 -> 46112
A4: Cash from Operating Activity | B4: ='Data Sheet'!B82 -> 5185 | C4: ='Data Sheet'!C82 -> 6059 | D4: ='Data Sheet'!D82 -> 5800 | E4: ='Data Sheet'!E82 -> 7623 | F4: ='Data Sheet'!F82 -> 9163 | G4: ='Data Sheet'!G82 -> 9048 | H4: ='Data Sheet'!H82 -> 9991 | I4: ='Data Sheet'!I82 -> 15469 | ... K4: ='Data Sheet'!K82 -> 10999
A5: Cash from Investing Activity | B5: ='Data Sheet'!B83 -> -1173 | C5: ='Data Sheet'!C83 -> -1063 | D5: ='Data Sheet'!D83 -> -438 | E5: ='Data Sheet'!E83 -> 1791 | F5: ='Data Sheet'!F83 -> -1228 | G5: ='Data Sheet'!G83 -> -1728 | H5: ='Data Sheet'!H83 -> -1484 | I5: ='Data Sheet'!I83 -> -5324 | ... K5: ='Data Sheet'!K83 -> -3676
A6: Cash from Financing Activity | B6: ='Data Sheet'!B84 -> -4214 | C6: ='Data Sheet'!C84 -> -4975 | D6: ='Data Sheet'!D84 -> -5390 | E6: ='Data Sheet'!E84 -> -6819 | F6: ='Data Sheet'!F84 -> -9309 | G6: ='Data Sheet'!G84 -> -8015 | H6: ='Data Sheet'!H84 -> -8953 | I6: ='Data Sheet'!I84 -> -10034 | ... K6: ='Data Sheet'!K84 -> -10810
A7: Net Cash Flow | B7: ='Data Sheet'!B85 -> -202 | C7: ='Data Sheet'!C85 -> 21 | D7: ='Data Sheet'!D85 -> -28 | E7: ='Data Sheet'!E85 -> 2595 | F7: ='Data Sheet'!F85 -> -1374 | G7: ='Data Sheet'!G85 -> -695 | H7: ='Data Sheet'!H85 -> -446 | I7: ='Data Sheet'!I85 -> 111 | ... K7: ='Data Sheet'!K85 -> -3487

Sheet Cash Flow Data
B3: Cash Flows
B4: Consolidated Figures in Rs. Crores / View Standalone
C5: 42064 | D5: 42430 | E5: 42795 | F5: 43160 | G5: 43525 | H5: 43891 | I5: 44256 | J5: 44621 | K5: 44986 | L5: 45352 | M5: 45717 | N5: 46082
B6: Cash from Operating Activity - | C6: 3292 | D6: 4171 | E6: 5185 | F6: 6059 | G6: 5800 | H6: 7623 | I6: 9163 | J6: 9048 | K6: 9991 | L6: 15469 | M6: 11886 | N6: 10999
B7: Profit from operations | C7: 5510 | D7: 6025 | E7: 6512 | F7: 7485 | G7: 8909 | H7: 9723 | I7: 11672 | J7: 12829 | K7: 14089 | L7: 14537 | M7: 14942 | N7: 15153
B8: Receivables | C8: 3 | D8: -257 | E8: 173 | F8: 0 | G8: 0 | H8: 0 | I8: 0 | J8: 0 | K8: 0 | L8: 0 | M8: 0 | N8: 0
B9: Inventory | C9: 91 | D9: 89 | E9: 37 | F9: -146 | G9: -195 | H9: -331 | I9: -543 | J9: -758 | K9: -339 | L9: 74 | M9: -584 | N9: -692
B10: Payables | C10: -327 | D10: 164 | E10: 501 | F10: 0 | G10: 0 | H10: 0 | I10: 0 | J10: 0 | K10: 0 | L10: 0 | M10: 0 | N10: 0
B11: Loans Advances | C11: -148 | D11: 0 | E11: 0 | F11: 0 | G11: 0 | H11: 0 | I11: 0 | J11: 0 | K11: 0 | L11: 0 | M11: 0 | N11: 0
B12: Operating Deposits | C12: 0 | D12: 0 | E12: -46 | F12: 0 | G12: 0 | H12: 0 | I12: 0 | J12: 0 | K12: 0 | L12: 0 | M12: 0 | N12: 0
B13: Other WC items | C13: 38 | D13: -77 | E13: -99 | F13: 982 | G13: -147 | H13: 742 | I13: 442 | J13: -242 | K13: -621 | L13: 1239 | M13: -204 | N13: 1378
B14: Working capital changes | C14: -342 | D14: -81 | E14: 566 | F14: 836 | G14: -342 | H14: 411 | I14: -101 | J14: -1000 | K14: -960 | L14: 1313 | M14: -788 | N14: 686
B15: Direct taxes | C15: -1862 | D15: -1765 | E15: -1859 | F15: -2264 | G15: -2767 | H15: -2505 | I15: -2407 | J15: -2784 | K15: -3138 | L15: -381 | M15: -2268 | N15: -4840
B16: Other operating items | C16: -14 | D16: -8 | E16: -21 | F16: 0 | G16: 0 | H16: 0 | I16: 0 | J16: 0 | K16: 0 | L16: 0 | M16: 0 | N16: 0
B17: Exceptional CF items | C17: 0 | D17: 0 | E17: -13 | F17: 2 | G17: 0 | H17: -6 | I17: -1 | J17: 3 | K17: 0 | L17: 0 | M17: 0 | N17: 0
... B38: CFO/OP | C38: 0.95 | D38: 1 | E38: 1.11 | F38: 1.11 | G38: 0.96 | H38: 1.03 | I38: 1 | J38: 0.92 | K38: 0.93 | L38: 1.08 | M38: 0.96 | N38: 1.05

Sheet Quarters
A1: ='Profit & Loss'!A1 -> HINDUSTAN UNILEVER LTD | E1: =UPDATE | J1: SCREENER.IN
A3: Narration | B3: ='Data Sheet'!B41 -> 45382 | C3: ='Data Sheet'!C41 -> 45473 | D3: ='Data Sheet'!D41 -> 45565 | E3: ='Data Sheet'!E41 -> 45657 | F3: ='Data Sheet'!F41 -> 45747 | G3: ='Data Sheet'!G41 -> 45838 | H3: ='Data Sheet'!H41 -> 45930 | I3: ='Data Sheet'!I41 -> 46022 | ... K3: ='Data Sheet'!K41 -> 46203
A4: Sales | B4: ='Data Sheet'!B42 -> 15210 | C4: ='Data Sheet'!C42 -> 15707 | D4: ='Data Sheet'!D42 -> 15926 | E4: ='Data Sheet'!E42 -> 15556 | F4: ='Data Sheet'!F42 -> 15190 | G4: ='Data Sheet'!G42 -> 15757 | H4: ='Data Sheet'!H42 -> 15919 | I4: ='Data Sheet'!I42 -> 16441 | ... K4: ='Data Sheet'!K42 -> 17341
A5: Expenses | B5: ='Data Sheet'!B43 -> 11675 | C5: ='Data Sheet'!C43 -> 11965 | D5: ='Data Sheet'!D43 -> 12139 | E5: ='Data Sheet'!E43 -> 11867 | F5: ='Data Sheet'!F43 -> 11572 | G5: ='Data Sheet'!G43 -> 12118 | H5: ='Data Sheet'!H43 -> 12137 | I5: ='Data Sheet'!I43 -> 12660 | ... K5: ='Data Sheet'!K43 -> 13394
A6: Operating Profit | B6: ='Data Sheet'!B50 -> 3535 | C6: ='Data Sheet'!C50 -> 3742 | D6: ='Data Sheet'!D50 -> 3787 | E6: ='Data Sheet'!E50 -> 3689 | F6: ='Data Sheet'!F50 -> 3618 | G6: ='Data Sheet'!G50 -> 3639 | H6: ='Data Sheet'!H50 -> 3782 | I6: ='Data Sheet'!I50 -> 3781 | ... K6: ='Data Sheet'!K50 -> 3947
A7: Other Income | B7: ='Data Sheet'!B44 -> 309 | C7: ='Data Sheet'!C44 -> 209 | D7: ='Data Sheet'!D44 -> 203 | E7: ='Data Sheet'!E44 -> 733 | F7: ='Data Sheet'!F44 -> 149 | G7: ='Data Sheet'!G44 -> 103 | H7: ='Data Sheet'!H44 -> 269 | I7: ='Data Sheet'!I44 -> 4048 | ... K7: ='Data Sheet'!K44 -> 113
A8: Depreciation | B8: ='Data Sheet'!B45 -> 320 | C8: ='Data Sheet'!C45 -> 329 | D8: ='Data Sheet'!D45 -> 338 | E8: ='Data Sheet'!E45 -> 318 | F8: ='Data Sheet'!F45 -> 318 | G8: ='Data Sheet'!G45 -> 326 | H8: ='Data Sheet'!H45 -> 322 | I8: ='Data Sheet'!I45 -> 337 | ... K8: ='Data Sheet'!K45 -> 353
A9: Interest | B9: ='Data Sheet'!B46 -> 105 | C9: ='Data Sheet'!C46 -> 93 | D9: ='Data Sheet'!D46 -> 110 | E9: ='Data Sheet'!E46 -> 109 | F9: ='Data Sheet'!F46 -> 77 | G9: ='Data Sheet'!G46 -> 122 | H9: ='Data Sheet'!H46 -> 124 | I9: ='Data Sheet'!I46 -> 88 | ... K9: ='Data Sheet'!K46 -> 75
A10: Profit before tax | B10: ='Data Sheet'!B47 -> 3419 | C10: ='Data Sheet'!C47 -> 3529 | D10: ='Data Sheet'!D47 -> 3542 | E10: ='Data Sheet'!E47 -> 3995 | F10: ='Data Sheet'!F47 -> 3372 | G10: ='Data Sheet'!G47 -> 3294 | H10: ='Data Sheet'!H47 -> 3605 | I10: ='Data Sheet'!I47 -> 7404 | ... K10: ='Data Sheet'!K47 -> 3632
A11: Tax | B11: ='Data Sheet'!B48 -> 858 | C11: ='Data Sheet'!C48 -> 917 | D11: ='Data Sheet'!D48 -> 947 | E11: ='Data Sheet'!E48 -> 1006 | F11: ='Data Sheet'!F48 -> 897 | G11: ='Data Sheet'!G48 -> 526 | H11: ='Data Sheet'!H48 -> 911 | I11: ='Data Sheet'!I48 -> 801 | ... K11: ='Data Sheet'!K48 -> 952
A12: Net profit | B12: ='Data Sheet'!B49 -> 2558 | C12: ='Data Sheet'!C49 -> 2610 | D12: ='Data Sheet'!D49 -> 2591 | E12: ='Data Sheet'!E49 -> 2984 | F12: ='Data Sheet'!F49 -> 2464 | G12: ='Data Sheet'!G49 -> 2756 | H12: ='Data Sheet'!H49 -> 2685 | I12: ='Data Sheet'!I49 -> 6607 | ... K12: ='Data Sheet'!K49 -> 2673
A14: OPM | B14: =IF(B4>0,B6/B4,"") -> 0.23241289 | C14: =IF(C4>0,C6/C4,"") -> 0.23823773 | D14: =IF(D4>0,D6/D4,"") -> 0.23778727 | E14: =IF(E4>0,E6/E4,"") -> 0.23714322 | F14: =IF(F4>0,F6/F4,"") -> 0.23818302 | G14: =IF(G4>0,G6/G4,"") -> 0.23094498 | H14: =IF(H4>0,H6/H4,"") -> 0.23757774 | I14: =IF(I4>0,I6/I4,"") -> 0.22997385 | ... K14: =IF(K4>0,K6/K4,"") -> 0.22761086

Sheet Common Size Statement
B2: 1. COMMON SIZE STATEMENT — PROFIT & LOSS ACCOUNT (Base = Net Sales = 100%)
B3: Particulars | C3: FY17 | D3: FY18 | E3: FY19 | F3: FY20 | G3: FY21 | H3: FY22 | I3: FY23 | J3: FY24 | K3: FY25 | L3: FY26
B4: Sales | C4: ='Data Sheet'!B17/'Data Sheet'!B$17 -> 1 | D4: ='Data Sheet'!C17/'Data Sheet'!C$17 -> 1 | E4: ='Data Sheet'!D17/'Data Sheet'!D$17 -> 1 | F4: ='Data Sheet'!E17/'Data Sheet'!E$17 -> 1 | G4: ='Data Sheet'!F17/'Data Sheet'!F$17 -> 1 | H4: ='Data Sheet'!G17/'Data Sheet'!G$17 -> 1 | I4: ='Data Sheet'!H17/'Data Sheet'!H$17 -> 1 | J4: ='Data Sheet'!I17/'Data Sheet'!I$17 -> 1 | ... L4: ='Data Sheet'!K17/'Data Sheet'!K$17 -> 1
B5: Raw Material Cost | C5: ='Data Sheet'!B18/'Data Sheet'!B$17 -> 0.41028888 | D5: ='Data Sheet'!C18/'Data Sheet'!C$17 -> 0.400422 | E5: ='Data Sheet'!D18/'Data Sheet'!D$17 -> 0.4030781 | F5: ='Data Sheet'!E18/'Data Sheet'!E$17 -> 0.39456552 | G5: ='Data Sheet'!F18/'Data Sheet'!F$17 -> 0.42827677 | H5: ='Data Sheet'!G18/'Data Sheet'!G$17 -> 0.43608664 | I5: ='Data Sheet'!H18/'Data Sheet'!H$17 -> 0.46924728 | J5: ='Data Sheet'!I18/'Data Sheet'!I$17 -> 0.4333398 | ... L5: ='Data Sheet'!K18/'Data Sheet'!K$17 -> 0.45228641
B6: Change in Inventory | C6: ='Data Sheet'!B19/'Data Sheet'!B$17 -> -0.0043423195 | D6: ='Data Sheet'!C19/'Data Sheet'!C$17 -> 0.0020256014 | E6: ='Data Sheet'!D19/'Data Sheet'!D$17 -> -0.00030526584 | F6: ='Data Sheet'!E19/'Data Sheet'!E$17 -> 0.0027147274 | G6: ='Data Sheet'!F19/'Data Sheet'!F$17 -> 0.0086118908 | H6: ='Data Sheet'!G19/'Data Sheet'!G$17 -> 0.00041947908 | I6: ='Data Sheet'!H19/'Data Sheet'!H$17 -> 0.0012380324 | J6: ='Data Sheet'!I19/'Data Sheet'!I$17 -> 0.00017771746 | ... L6: ='Data Sheet'!K19/'Data Sheet'!K$17 -> 0.0066544642
B7: Power and Fuel | C7: ='Data Sheet'!B20/'Data Sheet'!B$17 -> 0.008895724 | D7: ='Data Sheet'!C20/'Data Sheet'!C$17 -> 0.0082993389 | E7: ='Data Sheet'!D20/'Data Sheet'!D$17 -> 0.0078351564 | F7: ='Data Sheet'!E20/'Data Sheet'!E$17 -> 0.0075157731 | G7: ='Data Sheet'!F20/'Data Sheet'!F$17 -> 0.0072084715 | H7: ='Data Sheet'!G20/'Data Sheet'!G$17 -> 0.0060633795 | I7: ='Data Sheet'!H20/'Data Sheet'!H$17 -> 0.0063387257 | J7: ='Data Sheet'!I20/'Data Sheet'!I$17 -> 0.0072056353 | ... L7: ='Data Sheet'!K20/'Data Sheet'!K$17 -> 0.0066079295
B8: Other Mfr. Exp | C8: ='Data Sheet'!B21/'Data Sheet'!B$17 -> 0.087057475 | D8: ='Data Sheet'!C21/'Data Sheet'!C$17 -> 0.08434379 | E8: ='Data Sheet'!D21/'Data Sheet'!D$17 -> 0.077359451 | F8: ='Data Sheet'!E21/'Data Sheet'!E$17 -> 0.073046276 | G8: ='Data Sheet'!F21/'Data Sheet'!F$17 -> 0.060984945 | H8: ='Data Sheet'!G21/'Data Sheet'!G$17 -> 0.063951493 | I8: ='Data Sheet'!H21/'Data Sheet'!H$17 -> 0.062578409 | J8: ='Data Sheet'!I21/'Data Sheet'!I$17 -> 0.05468851 | ... L8: ='Data Sheet'!K21/'Data Sheet'!K$17 -> 0.051250233
B9: Employee Cost | C9: ='Data Sheet'!B22/'Data Sheet'!B$17 -> 0.052560159 | D9: ='Data Sheet'!C22/'Data Sheet'!C$17 -> 0.052328035 | E9: ='Data Sheet'!D22/'Data Sheet'!D$17 -> 0.047697787 | F9: ='Data Sheet'!E22/'Data Sheet'!E$17 -> 0.045748184 | G9: ='Data Sheet'!F22/'Data Sheet'!F$17 -> 0.050140342 | H9: ='Data Sheet'!G22/'Data Sheet'!G$17 -> 0.048526103 | I9: ='Data Sheet'!H22/'Data Sheet'!H$17 -> 0.047111258 | J9: ='Data Sheet'!I22/'Data Sheet'!I$17 -> 0.048613804 | ... L9: ='Data Sheet'!K22/'Data Sheet'!K$17 -> 0.04924924
B10: Selling and admin | C10: ='Data Sheet'!B23/'Data Sheet'!B$17 -> 0.20170677 | D10: ='Data Sheet'!C23/'Data Sheet'!C$17 -> 0.20402307 | E10: ='Data Sheet'!D23/'Data Sheet'!D$17 -> 0.19832104 | F10: ='Data Sheet'!E23/'Data Sheet'!E$17 -> 0.1915391 | G10: ='Data Sheet'!F23/'Data Sheet'!F$17 -> 0.16811261 | H10: ='Data Sheet'!G23/'Data Sheet'!G$17 -> 0.15566487 | I10: ='Data Sheet'!H23/'Data Sheet'!H$17 -> 0.14501486 | J10: ='Data Sheet'!I23/'Data Sheet'!I$17 -> 0.17416311 | ... L10: ='Data Sheet'!K23/'Data Sheet'!K$17 -> 0.16665633
